<?xml version="1.0"?>
<robot name="bee1" xmlns:xacro="http://www.ros.org/wiki/xacro">

  <!-- ── Araç Boyutları (BEE1) ─────────────────────────────── -->
  <xacro:property name="chassis_length" value="2.385"/>
  <xacro:property name="chassis_width"  value="1.330"/>
  <xacro:property name="chassis_height" value="0.185"/>
  <xacro:property name="wheel_radius"   value="0.15"/>
  <xacro:property name="wheel_width"    value="0.08"/>
  <xacro:property name="wheelbase"      value="2.40"/>
  <xacro:property name="track_width"    value="1.073"/>
  <xacro:property name="pi"             value="3.14159265"/>

  <!-- ── Base Link ─────────────────────────────────────────── -->
  <link name="base_link"/>

  <!-- ── Chassis ───────────────────────────────────────────── -->
  <joint name="chassis_joint" type="fixed">
    <parent link="base_link"/>
    <child link="chassis"/>
    <origin xyz="0 0 ${chassis_height/2 + wheel_radius}" rpy="0 0 0"/>
  </joint>

  <link name="chassis">
    <visual>
      <geometry>
        <box size="${chassis_length} ${chassis_width} ${chassis_height}"/>
      </geometry>
      <material name="white">
        <color rgba="0.9 0.9 0.9 1.0"/>
      </material>
    </visual>
    <collision>
      <geometry>
        <box size="${chassis_length} ${chassis_width} ${chassis_height}"/>
      </geometry>
    </collision>
    <inertial>
      <mass value="500.0"/>
      <inertia ixx="100" ixy="0" ixz="0" iyy="100" iyz="0" izz="100"/>
    </inertial>
  </link>

  <!-- ── Tekerlekler Macro ─────────────────────────────────── -->
  <xacro:macro name="wheel" params="name x y">
    <link name="${name}_wheel">
      <visual>
        <origin xyz="0 0 0" rpy="${pi/2} 0 0"/>
        <geometry>
          <cylinder radius="${wheel_radius}" length="${wheel_width}"/>
        </geometry>
        <material name="black">
          <color rgba="0.1 0.1 0.1 1.0"/>
        </material>
      </visual>
      <collision>
        <origin xyz="0 0 0" rpy="${pi/2} 0 0"/>
        <geometry>
          <cylinder radius="${wheel_radius}" length="${wheel_width}"/>
        </geometry>
      </collision>
      <inertial>
        <mass value="10.0"/>
        <inertia ixx="0.1" ixy="0" ixz="0" iyy="0.1" iyz="0" izz="0.1"/>
      </inertial>
    </link>
    <joint name="${name}_wheel_joint" type="continuous">
      <parent link="base_link"/>
      <child link="${name}_wheel"/>
      <origin xyz="${x} ${y} 0" rpy="0 0 0"/>
      <axis xyz="0 1 0"/>
    </joint>
  </xacro:macro>

  <!-- ── 4 Tekerlek ────────────────────────────────────────── -->
  <xacro:wheel name="front_left"  x="${wheelbase/2}"  y="${track_width/2}"/>
  <xacro:wheel name="front_right" x="${wheelbase/2}"  y="${-track_width/2}"/>
  <xacro:wheel name="rear_left"   x="${-wheelbase/2}" y="${track_width/2}"/>
  <xacro:wheel name="rear_right"  x="${-wheelbase/2}" y="${-track_width/2}"/>

  <!-- ── LiDAR (VLP-16) ────────────────────────────────────── -->
  <link name="lidar_frame">
    <visual>
      <geometry>
        <cylinder radius="0.05" length="0.07"/>
      </geometry>
      <material name="grey">
        <color rgba="0.5 0.5 0.5 1.0"/>
      </material>
    </visual>
  </link>
  <joint name="lidar_joint" type="fixed">
    <parent link="chassis"/>
    <child link="lidar_frame"/>
    <origin xyz="-0.177 0.0 0.435" rpy="0 0 0"/>
  </joint>

  <!-- ── ZED2 Kamera ───────────────────────────────────────── -->
  <link name="camera_frame">
    <visual>
      <geometry>
        <box size="0.12 0.03 0.03"/>
      </geometry>
      <material name="blue">
        <color rgba="0.0 0.0 0.8 1.0"/>
      </material>
    </visual>
  </link>
  <joint name="camera_joint" type="fixed">
    <parent link="chassis"/>
    <child link="camera_frame"/>
    <origin xyz="-0.205 0.0 0.500" rpy="0 0 0"/>
  </joint>

  <!-- ── IMU ───────────────────────────────────────────────── -->
  <link name="imu_frame"/>
  <joint name="imu_joint" type="fixed">
    <parent link="chassis"/>
    <child link="imu_frame"/>
    <origin xyz="0.0 0.0 0.0" rpy="0 0 0"/>
  </joint>

  <!-- ── Gazebo: Differential Drive ───────────────────────── -->
  <gazebo>
    <plugin name="differential_drive" filename="libgazebo_ros_diff_drive.so">
      <ros>
        <remapping>cmd_vel:=/cmd_vel</remapping>
        <remapping>odom:=/odom</remapping>
      </ros>
      <left_joint>rear_left_wheel_joint</left_joint>
      <right_joint>rear_right_wheel_joint</right_joint>
      <wheel_separation>${track_width}</wheel_separation>
      <wheel_diameter>${2*wheel_radius}</wheel_diameter>
      <max_wheel_torque>200</max_wheel_torque>
      <max_wheel_acceleration>10.0</max_wheel_acceleration>
      <publish_odom>true</publish_odom>
      <publish_odom_tf>true</publish_odom_tf>
      <publish_wheel_tf>true</publish_wheel_tf>
      <odometry_frame>odom</odometry_frame>
      <robot_base_frame>base_link</robot_base_frame>
    </plugin>
  </gazebo>

  <!-- ── Gazebo: LiDAR Plugin ──────────────────────────────── -->
  <gazebo reference="lidar_frame">
    <sensor type="ray" name="vlp16">
      <always_on>true</always_on>
      <update_rate>10</update_rate>
      <ray>
        <scan>
          <horizontal>
            <samples>360</samples>
            <resolution>1</resolution>
            <min_angle>-3.14159</min_angle>
            <max_angle>3.14159</max_angle>
          </horizontal>
          <vertical>
            <samples>16</samples>
            <resolution>1</resolution>
            <min_angle>-0.2618</min_angle>
            <max_angle>0.2618</max_angle>
          </vertical>
        </scan>
        <range>
          <min>0.1</min>
          <max>100.0</max>
          <resolution>0.01</resolution>
        </range>
      </ray>
      <plugin name="gazebo_ros_velodyne" filename="libgazebo_ros_ray_sensor.so">
        <ros>
          <remapping>~/out:=/velodyne_points</remapping>
        </ros>
        <output_type>sensor_msgs/PointCloud2</output_type>
        <frame_name>lidar_frame</frame_name>
      </plugin>
    </sensor>
  </gazebo>

  <!-- ── Gazebo: ZED2 Kamera Plugin ────────────────────────── -->
  <gazebo reference="camera_frame">
    <sensor type="camera" name="zed2_left">
      <always_on>true</always_on>
      <update_rate>30</update_rate>
      <camera>
        <horizontal_fov>1.9199</horizontal_fov>
        <image>
          <width>1280</width>
          <height>720</height>
          <format>R8G8B8</format>
        </image>
        <clip>
          <near>0.1</near>
          <far>100</far>
        </clip>
      </camera>
      <plugin name="gazebo_ros_camera" filename="libgazebo_ros_camera.so">
        <ros>
          <remapping>image_raw:=/zed2/left/image_raw</remapping>
          <remapping>camera_info:=/zed2/left/camera_info</remapping>
        </ros>
        <frame_name>camera_frame</frame_name>
      </plugin>
    </sensor>
  </gazebo>

  <!-- ── Gazebo: IMU Plugin ─────────────────────────────────── -->
  <gazebo reference="imu_frame">
    <sensor name="imu_sensor" type="imu">
      <always_on>true</always_on>
      <update_rate>100</update_rate>
      <plugin name="gazebo_ros_imu" filename="libgazebo_ros_imu_sensor.so">
        <ros>
          <remapping>~/out:=/imu/data</remapping>
        </ros>
        <initial_orientation_as_reference>false</initial_orientation_as_reference>
      </plugin>
    </sensor>
  </gazebo>

</robot>
