<?xml version="1.0" ?>
<!-- =================================================================================== -->
<!-- |    This document was autogenerated by xacro from bee1.urdf.xacro                | -->
<!-- |    EDITING THIS FILE BY HAND IS NOT RECOMMENDED                                 | -->
<!-- =================================================================================== -->
<robot name="bee1">
  <!-- ── Base Link ─────────────────────────────────────────── -->
  <link name="base_link"/>
  <!-- ── Chassis ───────────────────────────────────────────── -->
  <joint name="chassis_joint" type="fixed">
    <parent link="base_link"/>
    <child link="chassis"/>
    <origin rpy="0 0 0" xyz="0 0 0.2425"/>
  </joint>
  <link name="chassis">
    <visual>
      <geometry>
        <box size="2.385 1.33 0.185"/>
      </geometry>
      <material name="white">
        <color rgba="0.9 0.9 0.9 1.0"/>
      </material>
    </visual>
    <collision>
      <geometry>
        <box size="2.385 1.33 0.185"/>
      </geometry>
    </collision>
    <inertial>
      <mass value="500.0"/>
      <inertia ixx="100" ixy="0" ixz="0" iyy="100" iyz="0" izz="100"/>
    </inertial>
  </link>
  <link name="front_left_wheel">
    <visual>
      <origin rpy="1.570796325 0 0" xyz="0 0 0"/>
      <geometry>
        <cylinder length="0.08" radius="0.15"/>
      </geometry>
      <material name="black">
        <color rgba="0.1 0.1 0.1 1.0"/>
      </material>
    </visual>
    <collision>
      <origin rpy="1.570796325 0 0" xyz="0 0 0"/>
      <geometry>
        <cylinder length="0.08" radius="0.15"/>
      </geometry>
    </collision>
    <inertial>
      <mass value="10.0"/>
      <inertia ixx="0.1" ixy="0" ixz="0" iyy="0.1" iyz="0" izz="0.1"/>
    </inertial>
  </link>
  <joint name="front_left_wheel_joint" type="continuous">
    <parent link="base_link"/>
    <child link="front_left_wheel"/>
    <origin rpy="0 0 0" xyz="1.2 0.5365 0"/>
    <axis xyz="0 1 0"/>
  </joint>
  <link name="front_right_wheel">
    <visual>
      <origin rpy="1.570796325 0 0" xyz="0 0 0"/>
      <geometry>
        <cylinder length="0.08" radius="0.15"/>
      </geometry>
      <material name="black">
        <color rgba="0.1 0.1 0.1 1.0"/>
      </material>
    </visual>
    <collision>
      <origin rpy="1.570796325 0 0" xyz="0 0 0"/>
      <geometry>
        <cylinder length="0.08" radius="0.15"/>
      </geometry>
    </collision>
    <inertial>
      <mass value="10.0"/>
      <inertia ixx="0.1" ixy="0" ixz="0" iyy="0.1" iyz="0" izz="0.1"/>
    </inertial>
  </link>
  <joint name="front_right_wheel_joint" type="continuous">
    <parent link="base_link"/>
    <child link="front_right_wheel"/>
    <origin rpy="0 0 0" xyz="1.2 -0.5365 0"/>
    <axis xyz="0 1 0"/>
  </joint>
  <link name="rear_left_wheel">
    <visual>
      <origin rpy="1.570796325 0 0" xyz="0 0 0"/>
      <geometry>
        <cylinder length="0.08" radius="0.15"/>
      </geometry>
      <material name="black">
        <color rgba="0.1 0.1 0.1 1.0"/>
      </material>
    </visual>
    <collision>
      <origin rpy="1.570796325 0 0" xyz="0 0 0"/>
      <geometry>
        <cylinder length="0.08" radius="0.15"/>
      </geometry>
    </collision>
    <inertial>
      <mass value="10.0"/>
      <inertia ixx="0.1" ixy="0" ixz="0" iyy="0.1" iyz="0" izz="0.1"/>
    </inertial>
  </link>
  <joint name="rear_left_wheel_joint" type="continuous">
    <parent link="base_link"/>
    <child link="rear_left_wheel"/>
    <origin rpy="0 0 0" xyz="-1.2 0.5365 0"/>
    <axis xyz="0 1 0"/>
  </joint>
  <link name="rear_right_wheel">
    <visual>
      <origin rpy="1.570796325 0 0" xyz="0 0 0"/>
      <geometry>
        <cylinder length="0.08" radius="0.15"/>
      </geometry>
      <material name="black">
        <color rgba="0.1 0.1 0.1 1.0"/>
      </material>
    </visual>
    <collision>
      <origin rpy="1.570796325 0 0" xyz="0 0 0"/>
      <geometry>
        <cylinder length="0.08" radius="0.15"/>
      </geometry>
    </collision>
    <inertial>
      <mass value="10.0"/>
      <inertia ixx="0.1" ixy="0" ixz="0" iyy="0.1" iyz="0" izz="0.1"/>
    </inertial>
  </link>
  <joint name="rear_right_wheel_joint" type="continuous">
    <parent link="base_link"/>
    <child link="rear_right_wheel"/>
    <origin rpy="0 0 0" xyz="-1.2 -0.5365 0"/>
    <axis xyz="0 1 0"/>
  </joint>
  <!-- ── LiDAR (VLP-16) ────────────────────────────────────── -->
  <link name="lidar_frame">
    <visual>
      <geometry>
        <cylinder length="0.07" radius="0.05"/>
      </geometry>
      <material name="grey">
        <color rgba="0.5 0.5 0.5 1.0"/>
      </material>
    </visual>
  </link>
  <joint name="lidar_joint" type="fixed">
    <parent link="chassis"/>
    <child link="lidar_frame"/>
    <origin rpy="0 0 0" xyz="-0.177 0.0 0.435"/>
  </joint>
  <!-- ── ZED2 Kamera ───────────────────────────────────────── -->
  <link name="camera_frame">
    <visual>
      <geometry>
        <box size="0.12 0.03 0.03"/>
      </geometry>
      <material name="blue">
        <color rgba="0.0 0.0 0.8 1.0"/>
      </material>
    </visual>
  </link>
  <joint name="camera_joint" type="fixed">
    <parent link="chassis"/>
    <child link="camera_frame"/>
    <origin rpy="0 0 0" xyz="-0.205 0.0 0.500"/>
  </joint>
  <!-- ── IMU ───────────────────────────────────────────────── -->
  <link name="imu_frame"/>
  <joint name="imu_joint" type="fixed">
    <parent link="chassis"/>
    <child link="imu_frame"/>
    <origin rpy="0 0 0" xyz="0.0 0.0 0.0"/>
  </joint>
  <!-- ── Gazebo: Differential Drive ───────────────────────── -->
  <gazebo>
    <plugin filename="libgazebo_ros_diff_drive.so" name="differential_drive">
      <ros>
        <remapping>cmd_vel:=/cmd_vel</remapping>
        <remapping>odom:=/odom</remapping>
      </ros>
      <left_joint>rear_left_wheel_joint</left_joint>
      <right_joint>rear_right_wheel_joint</right_joint>
      <wheel_separation>1.073</wheel_separation>
      <wheel_diameter>0.3</wheel_diameter>
      <max_wheel_torque>200</max_wheel_torque>
      <max_wheel_acceleration>10.0</max_wheel_acceleration>
      <publish_odom>true</publish_odom>
      <publish_odom_tf>true</publish_odom_tf>
      <publish_wheel_tf>true</publish_wheel_tf>
      <odometry_frame>odom</odometry_frame>
      <robot_base_frame>base_link</robot_base_frame>
    </plugin>
  </gazebo>
  <!-- ── Gazebo: LiDAR Plugin ──────────────────────────────── -->
  <gazebo reference="lidar_frame">
    <sensor name="vlp16" type="ray">
      <always_on>true</always_on>
      <update_rate>10</update_rate>
      <ray>
        <scan>
          <horizontal>
            <samples>360</samples>
            <resolution>1</resolution>
            <min_angle>-3.14159</min_angle>
            <max_angle>3.14159</max_angle>
          </horizontal>
          <vertical>
            <samples>16</samples>
            <resolution>1</resolution>
            <min_angle>-0.2618</min_angle>
            <max_angle>0.2618</max_angle>
          </vertical>
        </scan>
        <range>
          <min>0.1</min>
          <max>100.0</max>
          <resolution>0.01</resolution>
        </range>
      </ray>
      <plugin filename="libgazebo_ros_ray_sensor.so" name="gazebo_ros_velodyne">
        <ros>
          <remapping>~/out:=/velodyne_points</remapping>
        </ros>
        <output_type>sensor_msgs/PointCloud2</output_type>
        <frame_name>lidar_frame</frame_name>
      </plugin>
    </sensor>
  </gazebo>
  <!-- ── Gazebo: ZED2 Kamera Plugin ────────────────────────── -->
  <gazebo reference="camera_frame">
    <sensor name="zed2_left" type="camera">
      <always_on>true</always_on>
      <update_rate>30</update_rate>
      <camera>
        <horizontal_fov>1.9199</horizontal_fov>
        <image>
          <width>1280</width>
          <height>720</height>
          <format>R8G8B8</format>
        </image>
        <clip>
          <near>0.1</near>
          <far>100</far>
        </clip>
      </camera>
      <plugin filename="libgazebo_ros_camera.so" name="gazebo_ros_camera">
        <ros>
          <remapping>image_raw:=/zed2/left/image_raw</remapping>
          <remapping>camera_info:=/zed2/left/camera_info</remapping>
        </ros>
        <frame_name>camera_frame</frame_name>
      </plugin>
    </sensor>
  </gazebo>
  <!-- ── Gazebo: IMU Plugin ─────────────────────────────────── -->
  <gazebo reference="imu_frame">
    <sensor name="imu_sensor" type="imu">
      <always_on>true</always_on>
      <update_rate>100</update_rate>
      <plugin filename="libgazebo_ros_imu_sensor.so" name="gazebo_ros_imu">
        <ros>
          <remapping>~/out:=/imu/data</remapping>
        </ros>
        <initial_orientation_as_reference>false</initial_orientation_as_reference>
      </plugin>
    </sensor>
  </gazebo>
</robot>
